<robot name="bot"
  xmlns:xacro="http://www.ros.org/wiki/xacro"
  xmlns:xi="http://www.w3.org/2001/XInclude">

  <xacro:property name="wheel_radius" value="0.0125"/>
  <xacro:property name="wheel_width" value="0.022"/>
  <xacro:property name="wheel_height" value="0.11"/>
  <xacro:property name="wheel_mass" value=".2"/>


  <joint name="left_wheel_joint" type="continuous">
    <origin xyz="0.554283 0.625029 0.3" rpy="-1.5707 0 0"/>
    <parent link="base_link"/>
    <child link="left_wheel"/>
    <axis xyz="0 0 1"/>
    <dynamics damping="0.2"/>
  </joint>

  <!-- left wheel Link -->
  <link name="left_wheel">
    <collision>
      <geometry>
        <sphere radius="0.3"/>
      </geometry>
    </collision>

    <visual>
      <geometry>
        <sphere radius="0.3"/>
      </geometry>
      <material name="black"/>
    </visual>

    <inertial>
      <mass value="2"/>
      <inertia ixx="0.145833" ixy="0.0" ixz="0.0" iyy="0.145833" iyz="0.0" izz="0.125"/>
    </inertial>
  </link>

  <joint name="right_wheel_joint" type="continuous">
    <origin xyz="0.554283 -0.625029 0.3" rpy="-1.5707 0 0"/>
    <parent link="base_link"/>
    <child link="right_wheel"/>
    <axis xyz="0 0 1"/>
    <dynamics damping="0.2"/>
  </joint>

  <!-- right wheel Link -->
  <link name="right_wheel">
    <collision>
      <geometry>
        <sphere radius="0.3"/>
      </geometry>
    </collision>

    <visual>
      <geometry>
        <sphere radius="0.3"/>
      </geometry>
      <material name="black"/>
    </visual>

    <inertial>
      <mass value="2"/>
      <inertia ixx="0.145833" ixy="0.0" ixz="0.0" iyy="0.145833" iyz="0.0" izz="0.125"/>
    </inertial>
  </link>

  <joint name="caster_joint" type="fixed">
    <origin xyz="-0.957138 -0 0.2" rpy="0 0 0"/>
    <parent link="base_link"/>
    <child link="caster"/>
  </joint>

  <!-- caster frontal wheel Link -->
  <link name="caster">
    <collision>
      <geometry>
        <sphere radius="0.2"/>
      </geometry>
    </collision>

    <visual>
      <geometry>
        <sphere radius="0.2"/>
      </geometry>
      <material name="white"/>
    </visual>

    <inertial>
      <origin xyz="-0.957138 -0 0.2" rpy="0 0 0"/>
      <mass value="0.005"/>
      <inertia ixx="0.1" ixy="0.0" ixz="0.0" iyy="0.1" iyz="0.0" izz="0.1"/>
    </inertial>
  </link>

</robot>
